<?xml version="1.0"?>
<robot name="roverArm">

	<material name="black">
    <color rgba="0 0 0 1"/>
  </material>

	<material name="silver">
		<color rgba="191 191 191 1"/>
	</material>


	<link name="base_link">
    <visual>
			<origin xyz="0 0 .75"/>
      <geometry>
        <box size=".04 .08 1.5"/>
      </geometry>
			<material name="silver"/>
    </visual>
  </link>

	<link name="linear_actuator">
    <!--<visual>
      <geometry>
        <cylinder length="1.5" radius="0.05"/>
      </geometry>
    </visual>-->
		<origin rpy="0 1.57 0" xyz="0.75 0 0.0"/>
  </link>

  <link name="link_1">
    <visual>
      <geometry>
        <cylinder length="0.6" radius="0.033"/>
      </geometry>
      <origin rpy="0 1.57 0" xyz="0.3 0 0.0"/>
			<material name="black"/>
    </visual>
  </link>	

	<!--<joint name="prismatic" type="prismatic">
    <parent link="base_link"/>
    <child link="link_1"/>
		<limit lower="0.0" upper="1.5" effort="100" velocity="50"/>
  </joint>-->

	<link name="link_2">
    <visual>
      <geometry>
        <cylinder length="0.4" radius="0.025"/>
      </geometry>
      <origin rpy="0 1.57075 0" xyz="0.2 0 0.0"/>
			<material name="black"/>
    </visual>
  </link>

	<link name="link_3">
    <visual>
      <geometry>
        <cylinder length="0.1" radius="0.025"/>
      </geometry>
      <origin rpy="0 1.57075 0" xyz="0.05 0 0.0"/>
			<material name="black"/>
    </visual>
  </link>	
		
	<link name="link_4">
    <visual>
      <geometry>
        <cylinder length="0.1" radius="0.01"/>
      </geometry>
      <origin rpy="0 1.57075 0" xyz="0.05 0 0.0"/>
			<material name="black"/>
    </visual>
  </link>

	<link name="link_5">
    <visual>
      <geometry>
        <cylinder length="0.1" radius="0.01"/>
      </geometry>
      <origin rpy="0 1.57075 0" xyz="0.05 0 0.0"/>
			<material name="black"/>
    </visual>
  </link>

	<link name="link_6">
    <visual>
      <geometry>
        <cylinder length="0.25" radius="0.01"/>
      </geometry>
      <origin rpy="0 1.57075 0" xyz="0.05 0 0.0"/>
			<material name="black"/>
    </visual>
  </link>	

	<link name="link_7">
    <visual>
      <geometry>
        <box size="0.05 0.1 0.1"/>
      </geometry>
      <origin rpy="0 1.57075 0" xyz="0.05 0 0.0"/>
			<material name="silver"/>
    </visual>
  </link>	

	<joint name="linear" type="prismatic">
    <parent link="base_link"/>
    <child link="linear_actuator"/>
		<limit lower="0" upper="1.5" effort="100" velocity="50"/>
		<axis xyz="0 0 1"/>
  </joint>

	<joint name="joint_1" type="revolute">
    <parent link="linear_actuator"/>
    <child link="link_1"/>
		<origin xyz=".1 0 0"/>
		<limit lower="-1.57" upper="1.57" effort="100" velocity="50"/>
		<axis xyz="0 0 1"/>
  </joint>
	
	<joint name="joint_2" type="revolute">
    <parent link="link_1"/>
    <child link="link_2"/>
		<limit lower="-1.57" upper="1.57" effort="100" velocity="50"/>
		<origin xyz="0.6 0 0"/>
		<axis xyz="0 0 1"/>
  </joint>

	<joint name="joint_3" type="revolute">
    <parent link="link_2"/>
    <child link="link_3"/>
		<limit lower="-1.57" upper="1.57" effort="100" velocity="50"/>
		<origin xyz="0.4 0 0"/>
		<axis xyz="0 0 1"/>
  </joint>

	<joint name="joint_4" type="revolute">
    <parent link="link_3"/>
    <child link="link_4"/>
		<limit lower="-6.28" upper="6.28" effort="100" velocity="50"/>
		<origin xyz="0.1 0 0"/>
		<axis xyz="1 0 0"/>
  </joint>

	<joint name="joint_5" type="revolute">
    <parent link="link_4"/>
    <child link="link_5"/>
		<limit lower="-1.57" upper="1.57" effort="100" velocity="50"/>
		<origin xyz="0.1 0 0"/>
		<axis xyz="0 0 1"/>
  </joint>

	<joint name="joint_6" type="revolute">
    <parent link="link_5"/>
    <child link="link_6"/>
		<limit lower="-6.28" upper="6.28" effort="100" velocity="50"/>
		<origin xyz="0.1 0 0"/>
		<axis xyz="1 0 0"/>
  </joint>

	<joint name="joint_7" type="fixed">
    <parent link="link_6"/>
    <child link="link_7"/>
		<origin xyz="0.1 0 0"/>
  </joint>


</robot>


